2025-02-11 11:43:07,739 -  nornir.core -     INFO -        run() - Running task 'ping_task' with args {} on 2 hosts
2025-02-11 11:43:07,833 - nornir.core.task -    ERROR -      start() - Host 'r1': task 'ping_task' failed with traceback:
Traceback (most recent call last):
  File "/home/vagrant/nornir/venv/lib/python3.10/site-packages/netmiko/base_connection.py", line 1142, in establish_connection
    self.remote_conn_pre.connect(**ssh_connect_params)
  File "/home/vagrant/nornir/venv/lib/python3.10/site-packages/paramiko/client.py", line 485, in connect
    self._auth(
  File "/home/vagrant/nornir/venv/lib/python3.10/site-packages/paramiko/client.py", line 819, in _auth
    raise SSHException("No authentication methods available")
paramiko.ssh_exception.SSHException: No authentication methods available

During handling of the above exception, another exception occurred:

Traceback (most recent call last):
  File "/home/vagrant/nornir/venv/lib/python3.10/site-packages/napalm/base/base.py", line 114, in _netmiko_open
    self._netmiko_device = ConnectHandler(
  File "/home/vagrant/nornir/venv/lib/python3.10/site-packages/netmiko/ssh_dispatcher.py", line 410, in ConnectHandler
    return ConnectionClass(*args, **kwargs)
  File "/home/vagrant/nornir/venv/lib/python3.10/site-packages/netmiko/base_connection.py", line 493, in __init__
    self._open()
  File "/home/vagrant/nornir/venv/lib/python3.10/site-packages/netmiko/base_connection.py", line 498, in _open
    self.establish_connection()
  File "/home/vagrant/nornir/venv/lib/python3.10/site-packages/netmiko/base_connection.py", line 1195, in establish_connection
    raise NetmikoTimeoutException(msg)
netmiko.exceptions.NetmikoTimeoutException: 
A paramiko SSHException occurred during connection creation:

No authentication methods available



During handling of the above exception, another exception occurred:

Traceback (most recent call last):
  File "/home/vagrant/nornir/venv/lib/python3.10/site-packages/nornir/core/task.py", line 98, in start
    r = self.task(self, **self.params)
  File "/home/vagrant/nornir/nornir-project/main.py", line 9, in ping_task
    napalm_conn = task.host.get_connection("napalm", task.nornir.config)
  File "/home/vagrant/nornir/venv/lib/python3.10/site-packages/nornir/core/inventory.py", line 476, in get_connection
    self.open_connection(
  File "/home/vagrant/nornir/venv/lib/python3.10/site-packages/nornir/core/inventory.py", line 528, in open_connection
    conn_obj.open(
  File "/home/vagrant/nornir/venv/lib/python3.10/site-packages/nornir_napalm/plugins/connections/__init__.py", line 57, in open
    connection.open()
  File "/home/vagrant/nornir/venv/lib/python3.10/site-packages/napalm/ios/ios.py", line 173, in open
    self.device = self._netmiko_open(
  File "/home/vagrant/nornir/venv/lib/python3.10/site-packages/napalm/base/base.py", line 123, in _netmiko_open
    raise ConnectionException("Cannot connect to {}".format(self.hostname))
napalm.base.exceptions.ConnectionException: Cannot connect to 192.168.121.101

2025-02-11 11:43:07,833 - nornir.core.task -    ERROR -      start() - Host 'r2': task 'ping_task' failed with traceback:
Traceback (most recent call last):
  File "/home/vagrant/nornir/venv/lib/python3.10/site-packages/netmiko/base_connection.py", line 1142, in establish_connection
    self.remote_conn_pre.connect(**ssh_connect_params)
  File "/home/vagrant/nornir/venv/lib/python3.10/site-packages/paramiko/client.py", line 485, in connect
    self._auth(
  File "/home/vagrant/nornir/venv/lib/python3.10/site-packages/paramiko/client.py", line 819, in _auth
    raise SSHException("No authentication methods available")
paramiko.ssh_exception.SSHException: No authentication methods available

During handling of the above exception, another exception occurred:

Traceback (most recent call last):
  File "/home/vagrant/nornir/venv/lib/python3.10/site-packages/napalm/base/base.py", line 114, in _netmiko_open
    self._netmiko_device = ConnectHandler(
  File "/home/vagrant/nornir/venv/lib/python3.10/site-packages/netmiko/ssh_dispatcher.py", line 410, in ConnectHandler
    return ConnectionClass(*args, **kwargs)
  File "/home/vagrant/nornir/venv/lib/python3.10/site-packages/netmiko/base_connection.py", line 493, in __init__
    self._open()
  File "/home/vagrant/nornir/venv/lib/python3.10/site-packages/netmiko/base_connection.py", line 498, in _open
    self.establish_connection()
  File "/home/vagrant/nornir/venv/lib/python3.10/site-packages/netmiko/base_connection.py", line 1195, in establish_connection
    raise NetmikoTimeoutException(msg)
netmiko.exceptions.NetmikoTimeoutException: 
A paramiko SSHException occurred during connection creation:

No authentication methods available



During handling of the above exception, another exception occurred:

Traceback (most recent call last):
  File "/home/vagrant/nornir/venv/lib/python3.10/site-packages/nornir/core/task.py", line 98, in start
    r = self.task(self, **self.params)
  File "/home/vagrant/nornir/nornir-project/main.py", line 9, in ping_task
    napalm_conn = task.host.get_connection("napalm", task.nornir.config)
  File "/home/vagrant/nornir/venv/lib/python3.10/site-packages/nornir/core/inventory.py", line 476, in get_connection
    self.open_connection(
  File "/home/vagrant/nornir/venv/lib/python3.10/site-packages/nornir/core/inventory.py", line 528, in open_connection
    conn_obj.open(
  File "/home/vagrant/nornir/venv/lib/python3.10/site-packages/nornir_napalm/plugins/connections/__init__.py", line 57, in open
    connection.open()
  File "/home/vagrant/nornir/venv/lib/python3.10/site-packages/napalm/ios/ios.py", line 173, in open
    self.device = self._netmiko_open(
  File "/home/vagrant/nornir/venv/lib/python3.10/site-packages/napalm/base/base.py", line 123, in _netmiko_open
    raise ConnectionException("Cannot connect to {}".format(self.hostname))
napalm.base.exceptions.ConnectionException: Cannot connect to 192.168.121.102

2025-02-11 11:43:55,630 -  nornir.core -     INFO -        run() - Running task 'ping_task' with args {} on 2 hosts
2025-02-11 11:43:55,721 - nornir.core.task -    ERROR -      start() - Host 'r1': task 'ping_task' failed with traceback:
Traceback (most recent call last):
  File "/home/vagrant/nornir/venv/lib/python3.10/site-packages/netmiko/base_connection.py", line 1142, in establish_connection
    self.remote_conn_pre.connect(**ssh_connect_params)
  File "/home/vagrant/nornir/venv/lib/python3.10/site-packages/paramiko/client.py", line 485, in connect
    self._auth(
  File "/home/vagrant/nornir/venv/lib/python3.10/site-packages/paramiko/client.py", line 819, in _auth
    raise SSHException("No authentication methods available")
paramiko.ssh_exception.SSHException: No authentication methods available

During handling of the above exception, another exception occurred:

Traceback (most recent call last):
  File "/home/vagrant/nornir/venv/lib/python3.10/site-packages/napalm/base/base.py", line 114, in _netmiko_open
    self._netmiko_device = ConnectHandler(
  File "/home/vagrant/nornir/venv/lib/python3.10/site-packages/netmiko/ssh_dispatcher.py", line 410, in ConnectHandler
    return ConnectionClass(*args, **kwargs)
  File "/home/vagrant/nornir/venv/lib/python3.10/site-packages/netmiko/base_connection.py", line 493, in __init__
    self._open()
  File "/home/vagrant/nornir/venv/lib/python3.10/site-packages/netmiko/base_connection.py", line 498, in _open
    self.establish_connection()
  File "/home/vagrant/nornir/venv/lib/python3.10/site-packages/netmiko/base_connection.py", line 1195, in establish_connection
    raise NetmikoTimeoutException(msg)
netmiko.exceptions.NetmikoTimeoutException: 
A paramiko SSHException occurred during connection creation:

No authentication methods available



During handling of the above exception, another exception occurred:

Traceback (most recent call last):
  File "/home/vagrant/nornir/venv/lib/python3.10/site-packages/nornir/core/task.py", line 98, in start
    r = self.task(self, **self.params)
  File "/home/vagrant/nornir/nornir-project/main.py", line 9, in ping_task
    napalm_conn = task.host.get_connection("napalm", task.nornir.config)
  File "/home/vagrant/nornir/venv/lib/python3.10/site-packages/nornir/core/inventory.py", line 476, in get_connection
    self.open_connection(
  File "/home/vagrant/nornir/venv/lib/python3.10/site-packages/nornir/core/inventory.py", line 528, in open_connection
    conn_obj.open(
  File "/home/vagrant/nornir/venv/lib/python3.10/site-packages/nornir_napalm/plugins/connections/__init__.py", line 57, in open
    connection.open()
  File "/home/vagrant/nornir/venv/lib/python3.10/site-packages/napalm/ios/ios.py", line 173, in open
    self.device = self._netmiko_open(
  File "/home/vagrant/nornir/venv/lib/python3.10/site-packages/napalm/base/base.py", line 123, in _netmiko_open
    raise ConnectionException("Cannot connect to {}".format(self.hostname))
napalm.base.exceptions.ConnectionException: Cannot connect to 192.168.121.101

2025-02-11 11:43:55,722 - nornir.core.task -    ERROR -      start() - Host 'r2': task 'ping_task' failed with traceback:
Traceback (most recent call last):
  File "/home/vagrant/nornir/venv/lib/python3.10/site-packages/netmiko/base_connection.py", line 1142, in establish_connection
    self.remote_conn_pre.connect(**ssh_connect_params)
  File "/home/vagrant/nornir/venv/lib/python3.10/site-packages/paramiko/client.py", line 485, in connect
    self._auth(
  File "/home/vagrant/nornir/venv/lib/python3.10/site-packages/paramiko/client.py", line 819, in _auth
    raise SSHException("No authentication methods available")
paramiko.ssh_exception.SSHException: No authentication methods available

During handling of the above exception, another exception occurred:

Traceback (most recent call last):
  File "/home/vagrant/nornir/venv/lib/python3.10/site-packages/napalm/base/base.py", line 114, in _netmiko_open
    self._netmiko_device = ConnectHandler(
  File "/home/vagrant/nornir/venv/lib/python3.10/site-packages/netmiko/ssh_dispatcher.py", line 410, in ConnectHandler
    return ConnectionClass(*args, **kwargs)
  File "/home/vagrant/nornir/venv/lib/python3.10/site-packages/netmiko/base_connection.py", line 493, in __init__
    self._open()
  File "/home/vagrant/nornir/venv/lib/python3.10/site-packages/netmiko/base_connection.py", line 498, in _open
    self.establish_connection()
  File "/home/vagrant/nornir/venv/lib/python3.10/site-packages/netmiko/base_connection.py", line 1195, in establish_connection
    raise NetmikoTimeoutException(msg)
netmiko.exceptions.NetmikoTimeoutException: 
A paramiko SSHException occurred during connection creation:

No authentication methods available



During handling of the above exception, another exception occurred:

Traceback (most recent call last):
  File "/home/vagrant/nornir/venv/lib/python3.10/site-packages/nornir/core/task.py", line 98, in start
    r = self.task(self, **self.params)
  File "/home/vagrant/nornir/nornir-project/main.py", line 9, in ping_task
    napalm_conn = task.host.get_connection("napalm", task.nornir.config)
  File "/home/vagrant/nornir/venv/lib/python3.10/site-packages/nornir/core/inventory.py", line 476, in get_connection
    self.open_connection(
  File "/home/vagrant/nornir/venv/lib/python3.10/site-packages/nornir/core/inventory.py", line 528, in open_connection
    conn_obj.open(
  File "/home/vagrant/nornir/venv/lib/python3.10/site-packages/nornir_napalm/plugins/connections/__init__.py", line 57, in open
    connection.open()
  File "/home/vagrant/nornir/venv/lib/python3.10/site-packages/napalm/ios/ios.py", line 173, in open
    self.device = self._netmiko_open(
  File "/home/vagrant/nornir/venv/lib/python3.10/site-packages/napalm/base/base.py", line 123, in _netmiko_open
    raise ConnectionException("Cannot connect to {}".format(self.hostname))
napalm.base.exceptions.ConnectionException: Cannot connect to 192.168.121.102

2025-02-11 11:44:46,130 -  nornir.core -     INFO -        run() - Running task 'ping_task' with args {} on 2 hosts
2025-02-11 11:44:46,237 - nornir.core.task -    ERROR -      start() - Host 'r1': task 'ping_task' failed with traceback:
Traceback (most recent call last):
  File "/home/vagrant/nornir/venv/lib/python3.10/site-packages/netmiko/base_connection.py", line 1142, in establish_connection
    self.remote_conn_pre.connect(**ssh_connect_params)
  File "/home/vagrant/nornir/venv/lib/python3.10/site-packages/paramiko/client.py", line 485, in connect
    self._auth(
  File "/home/vagrant/nornir/venv/lib/python3.10/site-packages/paramiko/client.py", line 819, in _auth
    raise SSHException("No authentication methods available")
paramiko.ssh_exception.SSHException: No authentication methods available

During handling of the above exception, another exception occurred:

Traceback (most recent call last):
  File "/home/vagrant/nornir/venv/lib/python3.10/site-packages/napalm/base/base.py", line 114, in _netmiko_open
    self._netmiko_device = ConnectHandler(
  File "/home/vagrant/nornir/venv/lib/python3.10/site-packages/netmiko/ssh_dispatcher.py", line 410, in ConnectHandler
    return ConnectionClass(*args, **kwargs)
  File "/home/vagrant/nornir/venv/lib/python3.10/site-packages/netmiko/base_connection.py", line 493, in __init__
    self._open()
  File "/home/vagrant/nornir/venv/lib/python3.10/site-packages/netmiko/base_connection.py", line 498, in _open
    self.establish_connection()
  File "/home/vagrant/nornir/venv/lib/python3.10/site-packages/netmiko/base_connection.py", line 1195, in establish_connection
    raise NetmikoTimeoutException(msg)
netmiko.exceptions.NetmikoTimeoutException: 
A paramiko SSHException occurred during connection creation:

No authentication methods available



During handling of the above exception, another exception occurred:

Traceback (most recent call last):
  File "/home/vagrant/nornir/venv/lib/python3.10/site-packages/nornir/core/task.py", line 98, in start
    r = self.task(self, **self.params)
  File "/home/vagrant/nornir/nornir-project/main.py", line 9, in ping_task
    napalm_conn = task.host.get_connection("napalm", task.nornir.config)
  File "/home/vagrant/nornir/venv/lib/python3.10/site-packages/nornir/core/inventory.py", line 476, in get_connection
    self.open_connection(
  File "/home/vagrant/nornir/venv/lib/python3.10/site-packages/nornir/core/inventory.py", line 528, in open_connection
    conn_obj.open(
  File "/home/vagrant/nornir/venv/lib/python3.10/site-packages/nornir_napalm/plugins/connections/__init__.py", line 57, in open
    connection.open()
  File "/home/vagrant/nornir/venv/lib/python3.10/site-packages/napalm/ios/ios.py", line 173, in open
    self.device = self._netmiko_open(
  File "/home/vagrant/nornir/venv/lib/python3.10/site-packages/napalm/base/base.py", line 123, in _netmiko_open
    raise ConnectionException("Cannot connect to {}".format(self.hostname))
napalm.base.exceptions.ConnectionException: Cannot connect to 192.168.121.101

2025-02-11 11:44:46,237 - nornir.core.task -    ERROR -      start() - Host 'r2': task 'ping_task' failed with traceback:
Traceback (most recent call last):
  File "/home/vagrant/nornir/venv/lib/python3.10/site-packages/netmiko/base_connection.py", line 1142, in establish_connection
    self.remote_conn_pre.connect(**ssh_connect_params)
  File "/home/vagrant/nornir/venv/lib/python3.10/site-packages/paramiko/client.py", line 485, in connect
    self._auth(
  File "/home/vagrant/nornir/venv/lib/python3.10/site-packages/paramiko/client.py", line 819, in _auth
    raise SSHException("No authentication methods available")
paramiko.ssh_exception.SSHException: No authentication methods available

During handling of the above exception, another exception occurred:

Traceback (most recent call last):
  File "/home/vagrant/nornir/venv/lib/python3.10/site-packages/napalm/base/base.py", line 114, in _netmiko_open
    self._netmiko_device = ConnectHandler(
  File "/home/vagrant/nornir/venv/lib/python3.10/site-packages/netmiko/ssh_dispatcher.py", line 410, in ConnectHandler
    return ConnectionClass(*args, **kwargs)
  File "/home/vagrant/nornir/venv/lib/python3.10/site-packages/netmiko/base_connection.py", line 493, in __init__
    self._open()
  File "/home/vagrant/nornir/venv/lib/python3.10/site-packages/netmiko/base_connection.py", line 498, in _open
    self.establish_connection()
  File "/home/vagrant/nornir/venv/lib/python3.10/site-packages/netmiko/base_connection.py", line 1195, in establish_connection
    raise NetmikoTimeoutException(msg)
netmiko.exceptions.NetmikoTimeoutException: 
A paramiko SSHException occurred during connection creation:

No authentication methods available



During handling of the above exception, another exception occurred:

Traceback (most recent call last):
  File "/home/vagrant/nornir/venv/lib/python3.10/site-packages/nornir/core/task.py", line 98, in start
    r = self.task(self, **self.params)
  File "/home/vagrant/nornir/nornir-project/main.py", line 9, in ping_task
    napalm_conn = task.host.get_connection("napalm", task.nornir.config)
  File "/home/vagrant/nornir/venv/lib/python3.10/site-packages/nornir/core/inventory.py", line 476, in get_connection
    self.open_connection(
  File "/home/vagrant/nornir/venv/lib/python3.10/site-packages/nornir/core/inventory.py", line 528, in open_connection
    conn_obj.open(
  File "/home/vagrant/nornir/venv/lib/python3.10/site-packages/nornir_napalm/plugins/connections/__init__.py", line 57, in open
    connection.open()
  File "/home/vagrant/nornir/venv/lib/python3.10/site-packages/napalm/ios/ios.py", line 173, in open
    self.device = self._netmiko_open(
  File "/home/vagrant/nornir/venv/lib/python3.10/site-packages/napalm/base/base.py", line 123, in _netmiko_open
    raise ConnectionException("Cannot connect to {}".format(self.hostname))
napalm.base.exceptions.ConnectionException: Cannot connect to 192.168.121.102

2025-02-11 11:48:22,140 -  nornir.core -     INFO -        run() - Running task 'ping_task' with args {} on 2 hosts
2025-02-11 11:48:22,248 - nornir.core.task -    ERROR -      start() - Host 'r1': task 'ping_task' failed with traceback:
Traceback (most recent call last):
  File "/home/vagrant/nornir/venv/lib/python3.10/site-packages/netmiko/base_connection.py", line 1142, in establish_connection
    self.remote_conn_pre.connect(**ssh_connect_params)
  File "/home/vagrant/nornir/venv/lib/python3.10/site-packages/paramiko/client.py", line 485, in connect
    self._auth(
  File "/home/vagrant/nornir/venv/lib/python3.10/site-packages/paramiko/client.py", line 819, in _auth
    raise SSHException("No authentication methods available")
paramiko.ssh_exception.SSHException: No authentication methods available

During handling of the above exception, another exception occurred:

Traceback (most recent call last):
  File "/home/vagrant/nornir/venv/lib/python3.10/site-packages/napalm/base/base.py", line 114, in _netmiko_open
    self._netmiko_device = ConnectHandler(
  File "/home/vagrant/nornir/venv/lib/python3.10/site-packages/netmiko/ssh_dispatcher.py", line 410, in ConnectHandler
    return ConnectionClass(*args, **kwargs)
  File "/home/vagrant/nornir/venv/lib/python3.10/site-packages/netmiko/base_connection.py", line 493, in __init__
    self._open()
  File "/home/vagrant/nornir/venv/lib/python3.10/site-packages/netmiko/base_connection.py", line 498, in _open
    self.establish_connection()
  File "/home/vagrant/nornir/venv/lib/python3.10/site-packages/netmiko/base_connection.py", line 1195, in establish_connection
    raise NetmikoTimeoutException(msg)
netmiko.exceptions.NetmikoTimeoutException: 
A paramiko SSHException occurred during connection creation:

No authentication methods available



During handling of the above exception, another exception occurred:

Traceback (most recent call last):
  File "/home/vagrant/nornir/venv/lib/python3.10/site-packages/nornir/core/task.py", line 98, in start
    r = self.task(self, **self.params)
  File "/home/vagrant/nornir/nornir-project/main.py", line 9, in ping_task
    napalm_conn = task.host.get_connection("napalm", task.nornir.config)
  File "/home/vagrant/nornir/venv/lib/python3.10/site-packages/nornir/core/inventory.py", line 476, in get_connection
    self.open_connection(
  File "/home/vagrant/nornir/venv/lib/python3.10/site-packages/nornir/core/inventory.py", line 528, in open_connection
    conn_obj.open(
  File "/home/vagrant/nornir/venv/lib/python3.10/site-packages/nornir_napalm/plugins/connections/__init__.py", line 57, in open
    connection.open()
  File "/home/vagrant/nornir/venv/lib/python3.10/site-packages/napalm/ios/ios.py", line 173, in open
    self.device = self._netmiko_open(
  File "/home/vagrant/nornir/venv/lib/python3.10/site-packages/napalm/base/base.py", line 123, in _netmiko_open
    raise ConnectionException("Cannot connect to {}".format(self.hostname))
napalm.base.exceptions.ConnectionException: Cannot connect to 192.168.121.101

2025-02-11 11:48:22,248 - nornir.core.task -    ERROR -      start() - Host 'r2': task 'ping_task' failed with traceback:
Traceback (most recent call last):
  File "/home/vagrant/nornir/venv/lib/python3.10/site-packages/netmiko/base_connection.py", line 1142, in establish_connection
    self.remote_conn_pre.connect(**ssh_connect_params)
  File "/home/vagrant/nornir/venv/lib/python3.10/site-packages/paramiko/client.py", line 485, in connect
    self._auth(
  File "/home/vagrant/nornir/venv/lib/python3.10/site-packages/paramiko/client.py", line 819, in _auth
    raise SSHException("No authentication methods available")
paramiko.ssh_exception.SSHException: No authentication methods available

During handling of the above exception, another exception occurred:

Traceback (most recent call last):
  File "/home/vagrant/nornir/venv/lib/python3.10/site-packages/napalm/base/base.py", line 114, in _netmiko_open
    self._netmiko_device = ConnectHandler(
  File "/home/vagrant/nornir/venv/lib/python3.10/site-packages/netmiko/ssh_dispatcher.py", line 410, in ConnectHandler
    return ConnectionClass(*args, **kwargs)
  File "/home/vagrant/nornir/venv/lib/python3.10/site-packages/netmiko/base_connection.py", line 493, in __init__
    self._open()
  File "/home/vagrant/nornir/venv/lib/python3.10/site-packages/netmiko/base_connection.py", line 498, in _open
    self.establish_connection()
  File "/home/vagrant/nornir/venv/lib/python3.10/site-packages/netmiko/base_connection.py", line 1195, in establish_connection
    raise NetmikoTimeoutException(msg)
netmiko.exceptions.NetmikoTimeoutException: 
A paramiko SSHException occurred during connection creation:

No authentication methods available



During handling of the above exception, another exception occurred:

Traceback (most recent call last):
  File "/home/vagrant/nornir/venv/lib/python3.10/site-packages/nornir/core/task.py", line 98, in start
    r = self.task(self, **self.params)
  File "/home/vagrant/nornir/nornir-project/main.py", line 9, in ping_task
    napalm_conn = task.host.get_connection("napalm", task.nornir.config)
  File "/home/vagrant/nornir/venv/lib/python3.10/site-packages/nornir/core/inventory.py", line 476, in get_connection
    self.open_connection(
  File "/home/vagrant/nornir/venv/lib/python3.10/site-packages/nornir/core/inventory.py", line 528, in open_connection
    conn_obj.open(
  File "/home/vagrant/nornir/venv/lib/python3.10/site-packages/nornir_napalm/plugins/connections/__init__.py", line 57, in open
    connection.open()
  File "/home/vagrant/nornir/venv/lib/python3.10/site-packages/napalm/ios/ios.py", line 173, in open
    self.device = self._netmiko_open(
  File "/home/vagrant/nornir/venv/lib/python3.10/site-packages/napalm/base/base.py", line 123, in _netmiko_open
    raise ConnectionException("Cannot connect to {}".format(self.hostname))
napalm.base.exceptions.ConnectionException: Cannot connect to 192.168.121.102

2025-02-11 11:53:57,020 -  nornir.core -     INFO -        run() - Running task 'ping_task' with args {} on 2 hosts
2025-02-11 11:53:57,126 - nornir.core.task -    ERROR -      start() - Host 'r1': task 'ping_task' failed with traceback:
Traceback (most recent call last):
  File "/home/vagrant/nornir/venv/lib/python3.10/site-packages/netmiko/base_connection.py", line 1142, in establish_connection
    self.remote_conn_pre.connect(**ssh_connect_params)
  File "/home/vagrant/nornir/venv/lib/python3.10/site-packages/paramiko/client.py", line 485, in connect
    self._auth(
  File "/home/vagrant/nornir/venv/lib/python3.10/site-packages/paramiko/client.py", line 819, in _auth
    raise SSHException("No authentication methods available")
paramiko.ssh_exception.SSHException: No authentication methods available

During handling of the above exception, another exception occurred:

Traceback (most recent call last):
  File "/home/vagrant/nornir/venv/lib/python3.10/site-packages/napalm/base/base.py", line 114, in _netmiko_open
    self._netmiko_device = ConnectHandler(
  File "/home/vagrant/nornir/venv/lib/python3.10/site-packages/netmiko/ssh_dispatcher.py", line 410, in ConnectHandler
    return ConnectionClass(*args, **kwargs)
  File "/home/vagrant/nornir/venv/lib/python3.10/site-packages/netmiko/base_connection.py", line 493, in __init__
    self._open()
  File "/home/vagrant/nornir/venv/lib/python3.10/site-packages/netmiko/base_connection.py", line 498, in _open
    self.establish_connection()
  File "/home/vagrant/nornir/venv/lib/python3.10/site-packages/netmiko/base_connection.py", line 1195, in establish_connection
    raise NetmikoTimeoutException(msg)
netmiko.exceptions.NetmikoTimeoutException: 
A paramiko SSHException occurred during connection creation:

No authentication methods available



During handling of the above exception, another exception occurred:

Traceback (most recent call last):
  File "/home/vagrant/nornir/venv/lib/python3.10/site-packages/nornir/core/task.py", line 98, in start
    r = self.task(self, **self.params)
  File "/home/vagrant/nornir/nornir-project/main.py", line 9, in ping_task
    napalm_conn = task.host.get_connection("napalm", task.nornir.config)
  File "/home/vagrant/nornir/venv/lib/python3.10/site-packages/nornir/core/inventory.py", line 476, in get_connection
    self.open_connection(
  File "/home/vagrant/nornir/venv/lib/python3.10/site-packages/nornir/core/inventory.py", line 528, in open_connection
    conn_obj.open(
  File "/home/vagrant/nornir/venv/lib/python3.10/site-packages/nornir_napalm/plugins/connections/__init__.py", line 57, in open
    connection.open()
  File "/home/vagrant/nornir/venv/lib/python3.10/site-packages/napalm/ios/ios.py", line 173, in open
    self.device = self._netmiko_open(
  File "/home/vagrant/nornir/venv/lib/python3.10/site-packages/napalm/base/base.py", line 123, in _netmiko_open
    raise ConnectionException("Cannot connect to {}".format(self.hostname))
napalm.base.exceptions.ConnectionException: Cannot connect to 192.168.121.101

2025-02-11 11:53:57,126 - nornir.core.task -    ERROR -      start() - Host 'r2': task 'ping_task' failed with traceback:
Traceback (most recent call last):
  File "/home/vagrant/nornir/venv/lib/python3.10/site-packages/netmiko/base_connection.py", line 1142, in establish_connection
    self.remote_conn_pre.connect(**ssh_connect_params)
  File "/home/vagrant/nornir/venv/lib/python3.10/site-packages/paramiko/client.py", line 485, in connect
    self._auth(
  File "/home/vagrant/nornir/venv/lib/python3.10/site-packages/paramiko/client.py", line 819, in _auth
    raise SSHException("No authentication methods available")
paramiko.ssh_exception.SSHException: No authentication methods available

During handling of the above exception, another exception occurred:

Traceback (most recent call last):
  File "/home/vagrant/nornir/venv/lib/python3.10/site-packages/napalm/base/base.py", line 114, in _netmiko_open
    self._netmiko_device = ConnectHandler(
  File "/home/vagrant/nornir/venv/lib/python3.10/site-packages/netmiko/ssh_dispatcher.py", line 410, in ConnectHandler
    return ConnectionClass(*args, **kwargs)
  File "/home/vagrant/nornir/venv/lib/python3.10/site-packages/netmiko/base_connection.py", line 493, in __init__
    self._open()
  File "/home/vagrant/nornir/venv/lib/python3.10/site-packages/netmiko/base_connection.py", line 498, in _open
    self.establish_connection()
  File "/home/vagrant/nornir/venv/lib/python3.10/site-packages/netmiko/base_connection.py", line 1195, in establish_connection
    raise NetmikoTimeoutException(msg)
netmiko.exceptions.NetmikoTimeoutException: 
A paramiko SSHException occurred during connection creation:

No authentication methods available



During handling of the above exception, another exception occurred:

Traceback (most recent call last):
  File "/home/vagrant/nornir/venv/lib/python3.10/site-packages/nornir/core/task.py", line 98, in start
    r = self.task(self, **self.params)
  File "/home/vagrant/nornir/nornir-project/main.py", line 9, in ping_task
    napalm_conn = task.host.get_connection("napalm", task.nornir.config)
  File "/home/vagrant/nornir/venv/lib/python3.10/site-packages/nornir/core/inventory.py", line 476, in get_connection
    self.open_connection(
  File "/home/vagrant/nornir/venv/lib/python3.10/site-packages/nornir/core/inventory.py", line 528, in open_connection
    conn_obj.open(
  File "/home/vagrant/nornir/venv/lib/python3.10/site-packages/nornir_napalm/plugins/connections/__init__.py", line 57, in open
    connection.open()
  File "/home/vagrant/nornir/venv/lib/python3.10/site-packages/napalm/ios/ios.py", line 173, in open
    self.device = self._netmiko_open(
  File "/home/vagrant/nornir/venv/lib/python3.10/site-packages/napalm/base/base.py", line 123, in _netmiko_open
    raise ConnectionException("Cannot connect to {}".format(self.hostname))
napalm.base.exceptions.ConnectionException: Cannot connect to 192.168.121.102

2025-02-11 11:55:26,002 -  nornir.core -     INFO -        run() - Running task 'napalm_get' with args {'getters': ['interfaces']} on 2 hosts
2025-02-11 11:55:26,094 - nornir.core.task -    ERROR -      start() - Host 'r2': task 'napalm_get' failed with traceback:
Traceback (most recent call last):
  File "/home/vagrant/nornir/venv/lib/python3.10/site-packages/netmiko/base_connection.py", line 1142, in establish_connection
    self.remote_conn_pre.connect(**ssh_connect_params)
  File "/home/vagrant/nornir/venv/lib/python3.10/site-packages/paramiko/client.py", line 485, in connect
    self._auth(
  File "/home/vagrant/nornir/venv/lib/python3.10/site-packages/paramiko/client.py", line 819, in _auth
    raise SSHException("No authentication methods available")
paramiko.ssh_exception.SSHException: No authentication methods available

During handling of the above exception, another exception occurred:

Traceback (most recent call last):
  File "/home/vagrant/nornir/venv/lib/python3.10/site-packages/napalm/base/base.py", line 114, in _netmiko_open
    self._netmiko_device = ConnectHandler(
  File "/home/vagrant/nornir/venv/lib/python3.10/site-packages/netmiko/ssh_dispatcher.py", line 410, in ConnectHandler
    return ConnectionClass(*args, **kwargs)
  File "/home/vagrant/nornir/venv/lib/python3.10/site-packages/netmiko/base_connection.py", line 493, in __init__
    self._open()
  File "/home/vagrant/nornir/venv/lib/python3.10/site-packages/netmiko/base_connection.py", line 498, in _open
    self.establish_connection()
  File "/home/vagrant/nornir/venv/lib/python3.10/site-packages/netmiko/base_connection.py", line 1195, in establish_connection
    raise NetmikoTimeoutException(msg)
netmiko.exceptions.NetmikoTimeoutException: 
A paramiko SSHException occurred during connection creation:

No authentication methods available



During handling of the above exception, another exception occurred:

Traceback (most recent call last):
  File "/home/vagrant/nornir/venv/lib/python3.10/site-packages/nornir/core/task.py", line 98, in start
    r = self.task(self, **self.params)
  File "/home/vagrant/nornir/venv/lib/python3.10/site-packages/nornir_napalm/plugins/tasks/napalm_get.py", line 32, in napalm_get
    device = task.host.get_connection(CONNECTION_NAME, task.nornir.config)
  File "/home/vagrant/nornir/venv/lib/python3.10/site-packages/nornir/core/inventory.py", line 476, in get_connection
    self.open_connection(
  File "/home/vagrant/nornir/venv/lib/python3.10/site-packages/nornir/core/inventory.py", line 528, in open_connection
    conn_obj.open(
  File "/home/vagrant/nornir/venv/lib/python3.10/site-packages/nornir_napalm/plugins/connections/__init__.py", line 57, in open
    connection.open()
  File "/home/vagrant/nornir/venv/lib/python3.10/site-packages/napalm/ios/ios.py", line 173, in open
    self.device = self._netmiko_open(
  File "/home/vagrant/nornir/venv/lib/python3.10/site-packages/napalm/base/base.py", line 123, in _netmiko_open
    raise ConnectionException("Cannot connect to {}".format(self.hostname))
napalm.base.exceptions.ConnectionException: Cannot connect to 192.168.121.102

2025-02-11 11:55:26,094 - nornir.core.task -    ERROR -      start() - Host 'r1': task 'napalm_get' failed with traceback:
Traceback (most recent call last):
  File "/home/vagrant/nornir/venv/lib/python3.10/site-packages/netmiko/base_connection.py", line 1142, in establish_connection
    self.remote_conn_pre.connect(**ssh_connect_params)
  File "/home/vagrant/nornir/venv/lib/python3.10/site-packages/paramiko/client.py", line 485, in connect
    self._auth(
  File "/home/vagrant/nornir/venv/lib/python3.10/site-packages/paramiko/client.py", line 819, in _auth
    raise SSHException("No authentication methods available")
paramiko.ssh_exception.SSHException: No authentication methods available

During handling of the above exception, another exception occurred:

Traceback (most recent call last):
  File "/home/vagrant/nornir/venv/lib/python3.10/site-packages/napalm/base/base.py", line 114, in _netmiko_open
    self._netmiko_device = ConnectHandler(
  File "/home/vagrant/nornir/venv/lib/python3.10/site-packages/netmiko/ssh_dispatcher.py", line 410, in ConnectHandler
    return ConnectionClass(*args, **kwargs)
  File "/home/vagrant/nornir/venv/lib/python3.10/site-packages/netmiko/base_connection.py", line 493, in __init__
    self._open()
  File "/home/vagrant/nornir/venv/lib/python3.10/site-packages/netmiko/base_connection.py", line 498, in _open
    self.establish_connection()
  File "/home/vagrant/nornir/venv/lib/python3.10/site-packages/netmiko/base_connection.py", line 1195, in establish_connection
    raise NetmikoTimeoutException(msg)
netmiko.exceptions.NetmikoTimeoutException: 
A paramiko SSHException occurred during connection creation:

No authentication methods available



During handling of the above exception, another exception occurred:

Traceback (most recent call last):
  File "/home/vagrant/nornir/venv/lib/python3.10/site-packages/nornir/core/task.py", line 98, in start
    r = self.task(self, **self.params)
  File "/home/vagrant/nornir/venv/lib/python3.10/site-packages/nornir_napalm/plugins/tasks/napalm_get.py", line 32, in napalm_get
    device = task.host.get_connection(CONNECTION_NAME, task.nornir.config)
  File "/home/vagrant/nornir/venv/lib/python3.10/site-packages/nornir/core/inventory.py", line 476, in get_connection
    self.open_connection(
  File "/home/vagrant/nornir/venv/lib/python3.10/site-packages/nornir/core/inventory.py", line 528, in open_connection
    conn_obj.open(
  File "/home/vagrant/nornir/venv/lib/python3.10/site-packages/nornir_napalm/plugins/connections/__init__.py", line 57, in open
    connection.open()
  File "/home/vagrant/nornir/venv/lib/python3.10/site-packages/napalm/ios/ios.py", line 173, in open
    self.device = self._netmiko_open(
  File "/home/vagrant/nornir/venv/lib/python3.10/site-packages/napalm/base/base.py", line 123, in _netmiko_open
    raise ConnectionException("Cannot connect to {}".format(self.hostname))
napalm.base.exceptions.ConnectionException: Cannot connect to 192.168.121.101

2025-02-11 11:56:19,762 -  nornir.core -     INFO -        run() - Running task 'napalm_get' with args {'getters': ['interfaces']} on 2 hosts
2025-02-11 11:56:19,870 - nornir.core.task -    ERROR -      start() - Host 'r1': task 'napalm_get' failed with traceback:
Traceback (most recent call last):
  File "/home/vagrant/nornir/venv/lib/python3.10/site-packages/netmiko/base_connection.py", line 1142, in establish_connection
    self.remote_conn_pre.connect(**ssh_connect_params)
  File "/home/vagrant/nornir/venv/lib/python3.10/site-packages/paramiko/client.py", line 485, in connect
    self._auth(
  File "/home/vagrant/nornir/venv/lib/python3.10/site-packages/paramiko/client.py", line 819, in _auth
    raise SSHException("No authentication methods available")
paramiko.ssh_exception.SSHException: No authentication methods available

During handling of the above exception, another exception occurred:

Traceback (most recent call last):
  File "/home/vagrant/nornir/venv/lib/python3.10/site-packages/napalm/base/base.py", line 114, in _netmiko_open
    self._netmiko_device = ConnectHandler(
  File "/home/vagrant/nornir/venv/lib/python3.10/site-packages/netmiko/ssh_dispatcher.py", line 410, in ConnectHandler
    return ConnectionClass(*args, **kwargs)
  File "/home/vagrant/nornir/venv/lib/python3.10/site-packages/netmiko/base_connection.py", line 493, in __init__
    self._open()
  File "/home/vagrant/nornir/venv/lib/python3.10/site-packages/netmiko/base_connection.py", line 498, in _open
    self.establish_connection()
  File "/home/vagrant/nornir/venv/lib/python3.10/site-packages/netmiko/base_connection.py", line 1195, in establish_connection
    raise NetmikoTimeoutException(msg)
netmiko.exceptions.NetmikoTimeoutException: 
A paramiko SSHException occurred during connection creation:

No authentication methods available



During handling of the above exception, another exception occurred:

Traceback (most recent call last):
  File "/home/vagrant/nornir/venv/lib/python3.10/site-packages/nornir/core/task.py", line 98, in start
    r = self.task(self, **self.params)
  File "/home/vagrant/nornir/venv/lib/python3.10/site-packages/nornir_napalm/plugins/tasks/napalm_get.py", line 32, in napalm_get
    device = task.host.get_connection(CONNECTION_NAME, task.nornir.config)
  File "/home/vagrant/nornir/venv/lib/python3.10/site-packages/nornir/core/inventory.py", line 476, in get_connection
    self.open_connection(
  File "/home/vagrant/nornir/venv/lib/python3.10/site-packages/nornir/core/inventory.py", line 528, in open_connection
    conn_obj.open(
  File "/home/vagrant/nornir/venv/lib/python3.10/site-packages/nornir_napalm/plugins/connections/__init__.py", line 57, in open
    connection.open()
  File "/home/vagrant/nornir/venv/lib/python3.10/site-packages/napalm/ios/ios.py", line 173, in open
    self.device = self._netmiko_open(
  File "/home/vagrant/nornir/venv/lib/python3.10/site-packages/napalm/base/base.py", line 123, in _netmiko_open
    raise ConnectionException("Cannot connect to {}".format(self.hostname))
napalm.base.exceptions.ConnectionException: Cannot connect to 192.168.121.101

2025-02-11 11:56:19,870 - nornir.core.task -    ERROR -      start() - Host 'r2': task 'napalm_get' failed with traceback:
Traceback (most recent call last):
  File "/home/vagrant/nornir/venv/lib/python3.10/site-packages/netmiko/base_connection.py", line 1142, in establish_connection
    self.remote_conn_pre.connect(**ssh_connect_params)
  File "/home/vagrant/nornir/venv/lib/python3.10/site-packages/paramiko/client.py", line 485, in connect
    self._auth(
  File "/home/vagrant/nornir/venv/lib/python3.10/site-packages/paramiko/client.py", line 819, in _auth
    raise SSHException("No authentication methods available")
paramiko.ssh_exception.SSHException: No authentication methods available

During handling of the above exception, another exception occurred:

Traceback (most recent call last):
  File "/home/vagrant/nornir/venv/lib/python3.10/site-packages/napalm/base/base.py", line 114, in _netmiko_open
    self._netmiko_device = ConnectHandler(
  File "/home/vagrant/nornir/venv/lib/python3.10/site-packages/netmiko/ssh_dispatcher.py", line 410, in ConnectHandler
    return ConnectionClass(*args, **kwargs)
  File "/home/vagrant/nornir/venv/lib/python3.10/site-packages/netmiko/base_connection.py", line 493, in __init__
    self._open()
  File "/home/vagrant/nornir/venv/lib/python3.10/site-packages/netmiko/base_connection.py", line 498, in _open
    self.establish_connection()
  File "/home/vagrant/nornir/venv/lib/python3.10/site-packages/netmiko/base_connection.py", line 1195, in establish_connection
    raise NetmikoTimeoutException(msg)
netmiko.exceptions.NetmikoTimeoutException: 
A paramiko SSHException occurred during connection creation:

No authentication methods available



During handling of the above exception, another exception occurred:

Traceback (most recent call last):
  File "/home/vagrant/nornir/venv/lib/python3.10/site-packages/nornir/core/task.py", line 98, in start
    r = self.task(self, **self.params)
  File "/home/vagrant/nornir/venv/lib/python3.10/site-packages/nornir_napalm/plugins/tasks/napalm_get.py", line 32, in napalm_get
    device = task.host.get_connection(CONNECTION_NAME, task.nornir.config)
  File "/home/vagrant/nornir/venv/lib/python3.10/site-packages/nornir/core/inventory.py", line 476, in get_connection
    self.open_connection(
  File "/home/vagrant/nornir/venv/lib/python3.10/site-packages/nornir/core/inventory.py", line 528, in open_connection
    conn_obj.open(
  File "/home/vagrant/nornir/venv/lib/python3.10/site-packages/nornir_napalm/plugins/connections/__init__.py", line 57, in open
    connection.open()
  File "/home/vagrant/nornir/venv/lib/python3.10/site-packages/napalm/ios/ios.py", line 173, in open
    self.device = self._netmiko_open(
  File "/home/vagrant/nornir/venv/lib/python3.10/site-packages/napalm/base/base.py", line 123, in _netmiko_open
    raise ConnectionException("Cannot connect to {}".format(self.hostname))
napalm.base.exceptions.ConnectionException: Cannot connect to 192.168.121.102

2025-02-11 11:56:53,863 -  nornir.core -     INFO -        run() - Running task 'napalm_get' with args {'getters': ['interfaces']} on 2 hosts
2025-02-11 11:56:53,956 - nornir.core.task -    ERROR -      start() - Host 'r1': task 'napalm_get' failed with traceback:
Traceback (most recent call last):
  File "/home/vagrant/nornir/venv/lib/python3.10/site-packages/netmiko/base_connection.py", line 1142, in establish_connection
    self.remote_conn_pre.connect(**ssh_connect_params)
  File "/home/vagrant/nornir/venv/lib/python3.10/site-packages/paramiko/client.py", line 485, in connect
    self._auth(
  File "/home/vagrant/nornir/venv/lib/python3.10/site-packages/paramiko/client.py", line 819, in _auth
    raise SSHException("No authentication methods available")
paramiko.ssh_exception.SSHException: No authentication methods available

During handling of the above exception, another exception occurred:

Traceback (most recent call last):
  File "/home/vagrant/nornir/venv/lib/python3.10/site-packages/napalm/base/base.py", line 114, in _netmiko_open
    self._netmiko_device = ConnectHandler(
  File "/home/vagrant/nornir/venv/lib/python3.10/site-packages/netmiko/ssh_dispatcher.py", line 410, in ConnectHandler
    return ConnectionClass(*args, **kwargs)
  File "/home/vagrant/nornir/venv/lib/python3.10/site-packages/netmiko/base_connection.py", line 493, in __init__
    self._open()
  File "/home/vagrant/nornir/venv/lib/python3.10/site-packages/netmiko/base_connection.py", line 498, in _open
    self.establish_connection()
  File "/home/vagrant/nornir/venv/lib/python3.10/site-packages/netmiko/base_connection.py", line 1195, in establish_connection
    raise NetmikoTimeoutException(msg)
netmiko.exceptions.NetmikoTimeoutException: 
A paramiko SSHException occurred during connection creation:

No authentication methods available



During handling of the above exception, another exception occurred:

Traceback (most recent call last):
  File "/home/vagrant/nornir/venv/lib/python3.10/site-packages/nornir/core/task.py", line 98, in start
    r = self.task(self, **self.params)
  File "/home/vagrant/nornir/venv/lib/python3.10/site-packages/nornir_napalm/plugins/tasks/napalm_get.py", line 32, in napalm_get
    device = task.host.get_connection(CONNECTION_NAME, task.nornir.config)
  File "/home/vagrant/nornir/venv/lib/python3.10/site-packages/nornir/core/inventory.py", line 476, in get_connection
    self.open_connection(
  File "/home/vagrant/nornir/venv/lib/python3.10/site-packages/nornir/core/inventory.py", line 528, in open_connection
    conn_obj.open(
  File "/home/vagrant/nornir/venv/lib/python3.10/site-packages/nornir_napalm/plugins/connections/__init__.py", line 57, in open
    connection.open()
  File "/home/vagrant/nornir/venv/lib/python3.10/site-packages/napalm/ios/ios.py", line 173, in open
    self.device = self._netmiko_open(
  File "/home/vagrant/nornir/venv/lib/python3.10/site-packages/napalm/base/base.py", line 123, in _netmiko_open
    raise ConnectionException("Cannot connect to {}".format(self.hostname))
napalm.base.exceptions.ConnectionException: Cannot connect to 192.168.121.101

2025-02-11 11:56:53,956 - nornir.core.task -    ERROR -      start() - Host 'r2': task 'napalm_get' failed with traceback:
Traceback (most recent call last):
  File "/home/vagrant/nornir/venv/lib/python3.10/site-packages/netmiko/base_connection.py", line 1142, in establish_connection
    self.remote_conn_pre.connect(**ssh_connect_params)
  File "/home/vagrant/nornir/venv/lib/python3.10/site-packages/paramiko/client.py", line 485, in connect
    self._auth(
  File "/home/vagrant/nornir/venv/lib/python3.10/site-packages/paramiko/client.py", line 819, in _auth
    raise SSHException("No authentication methods available")
paramiko.ssh_exception.SSHException: No authentication methods available

During handling of the above exception, another exception occurred:

Traceback (most recent call last):
  File "/home/vagrant/nornir/venv/lib/python3.10/site-packages/napalm/base/base.py", line 114, in _netmiko_open
    self._netmiko_device = ConnectHandler(
  File "/home/vagrant/nornir/venv/lib/python3.10/site-packages/netmiko/ssh_dispatcher.py", line 410, in ConnectHandler
    return ConnectionClass(*args, **kwargs)
  File "/home/vagrant/nornir/venv/lib/python3.10/site-packages/netmiko/base_connection.py", line 493, in __init__
    self._open()
  File "/home/vagrant/nornir/venv/lib/python3.10/site-packages/netmiko/base_connection.py", line 498, in _open
    self.establish_connection()
  File "/home/vagrant/nornir/venv/lib/python3.10/site-packages/netmiko/base_connection.py", line 1195, in establish_connection
    raise NetmikoTimeoutException(msg)
netmiko.exceptions.NetmikoTimeoutException: 
A paramiko SSHException occurred during connection creation:

No authentication methods available



During handling of the above exception, another exception occurred:

Traceback (most recent call last):
  File "/home/vagrant/nornir/venv/lib/python3.10/site-packages/nornir/core/task.py", line 98, in start
    r = self.task(self, **self.params)
  File "/home/vagrant/nornir/venv/lib/python3.10/site-packages/nornir_napalm/plugins/tasks/napalm_get.py", line 32, in napalm_get
    device = task.host.get_connection(CONNECTION_NAME, task.nornir.config)
  File "/home/vagrant/nornir/venv/lib/python3.10/site-packages/nornir/core/inventory.py", line 476, in get_connection
    self.open_connection(
  File "/home/vagrant/nornir/venv/lib/python3.10/site-packages/nornir/core/inventory.py", line 528, in open_connection
    conn_obj.open(
  File "/home/vagrant/nornir/venv/lib/python3.10/site-packages/nornir_napalm/plugins/connections/__init__.py", line 57, in open
    connection.open()
  File "/home/vagrant/nornir/venv/lib/python3.10/site-packages/napalm/ios/ios.py", line 173, in open
    self.device = self._netmiko_open(
  File "/home/vagrant/nornir/venv/lib/python3.10/site-packages/napalm/base/base.py", line 123, in _netmiko_open
    raise ConnectionException("Cannot connect to {}".format(self.hostname))
napalm.base.exceptions.ConnectionException: Cannot connect to 192.168.121.102

2025-02-11 11:58:41,374 -  nornir.core -     INFO -        run() - Running task 'napalm_get' with args {'getters': ['interfaces']} on 1 hosts
2025-02-11 11:58:41,375 - nornir.core.task -    ERROR -      start() - Host 'hosts': task 'napalm_get' failed with traceback:
Traceback (most recent call last):
  File "/home/vagrant/nornir/venv/lib/python3.10/site-packages/nornir/core/task.py", line 98, in start
    r = self.task(self, **self.params)
  File "/home/vagrant/nornir/venv/lib/python3.10/site-packages/nornir_napalm/plugins/tasks/napalm_get.py", line 32, in napalm_get
    device = task.host.get_connection(CONNECTION_NAME, task.nornir.config)
  File "/home/vagrant/nornir/venv/lib/python3.10/site-packages/nornir/core/inventory.py", line 476, in get_connection
    self.open_connection(
  File "/home/vagrant/nornir/venv/lib/python3.10/site-packages/nornir/core/inventory.py", line 528, in open_connection
    conn_obj.open(
  File "/home/vagrant/nornir/venv/lib/python3.10/site-packages/nornir_napalm/plugins/connections/__init__.py", line 55, in open
    network_driver = get_network_driver(platform)
  File "/home/vagrant/nornir/venv/lib/python3.10/site-packages/napalm/base/__init__.py", line 70, in get_network_driver
    raise ModuleImportError("Please provide a valid driver name.")
napalm.base.exceptions.ModuleImportError: Please provide a valid driver name.

2025-02-11 11:59:24,475 -  nornir.core -     INFO -        run() - Running task 'napalm_get' with args {'getters': ['interfaces']} on 2 hosts
2025-02-11 11:59:24,583 - nornir.core.task -    ERROR -      start() - Host 'r2': task 'napalm_get' failed with traceback:
Traceback (most recent call last):
  File "/home/vagrant/nornir/venv/lib/python3.10/site-packages/netmiko/base_connection.py", line 1142, in establish_connection
    self.remote_conn_pre.connect(**ssh_connect_params)
  File "/home/vagrant/nornir/venv/lib/python3.10/site-packages/paramiko/client.py", line 485, in connect
    self._auth(
  File "/home/vagrant/nornir/venv/lib/python3.10/site-packages/paramiko/client.py", line 819, in _auth
    raise SSHException("No authentication methods available")
paramiko.ssh_exception.SSHException: No authentication methods available

During handling of the above exception, another exception occurred:

Traceback (most recent call last):
  File "/home/vagrant/nornir/venv/lib/python3.10/site-packages/napalm/base/base.py", line 114, in _netmiko_open
    self._netmiko_device = ConnectHandler(
  File "/home/vagrant/nornir/venv/lib/python3.10/site-packages/netmiko/ssh_dispatcher.py", line 410, in ConnectHandler
    return ConnectionClass(*args, **kwargs)
  File "/home/vagrant/nornir/venv/lib/python3.10/site-packages/netmiko/base_connection.py", line 493, in __init__
    self._open()
  File "/home/vagrant/nornir/venv/lib/python3.10/site-packages/netmiko/base_connection.py", line 498, in _open
    self.establish_connection()
  File "/home/vagrant/nornir/venv/lib/python3.10/site-packages/netmiko/base_connection.py", line 1195, in establish_connection
    raise NetmikoTimeoutException(msg)
netmiko.exceptions.NetmikoTimeoutException: 
A paramiko SSHException occurred during connection creation:

No authentication methods available



During handling of the above exception, another exception occurred:

Traceback (most recent call last):
  File "/home/vagrant/nornir/venv/lib/python3.10/site-packages/nornir/core/task.py", line 98, in start
    r = self.task(self, **self.params)
  File "/home/vagrant/nornir/venv/lib/python3.10/site-packages/nornir_napalm/plugins/tasks/napalm_get.py", line 32, in napalm_get
    device = task.host.get_connection(CONNECTION_NAME, task.nornir.config)
  File "/home/vagrant/nornir/venv/lib/python3.10/site-packages/nornir/core/inventory.py", line 476, in get_connection
    self.open_connection(
  File "/home/vagrant/nornir/venv/lib/python3.10/site-packages/nornir/core/inventory.py", line 528, in open_connection
    conn_obj.open(
  File "/home/vagrant/nornir/venv/lib/python3.10/site-packages/nornir_napalm/plugins/connections/__init__.py", line 57, in open
    connection.open()
  File "/home/vagrant/nornir/venv/lib/python3.10/site-packages/napalm/ios/ios.py", line 173, in open
    self.device = self._netmiko_open(
  File "/home/vagrant/nornir/venv/lib/python3.10/site-packages/napalm/base/base.py", line 123, in _netmiko_open
    raise ConnectionException("Cannot connect to {}".format(self.hostname))
napalm.base.exceptions.ConnectionException: Cannot connect to 192.168.121.102

2025-02-11 11:59:24,583 - nornir.core.task -    ERROR -      start() - Host 'r1': task 'napalm_get' failed with traceback:
Traceback (most recent call last):
  File "/home/vagrant/nornir/venv/lib/python3.10/site-packages/netmiko/base_connection.py", line 1142, in establish_connection
    self.remote_conn_pre.connect(**ssh_connect_params)
  File "/home/vagrant/nornir/venv/lib/python3.10/site-packages/paramiko/client.py", line 485, in connect
    self._auth(
  File "/home/vagrant/nornir/venv/lib/python3.10/site-packages/paramiko/client.py", line 819, in _auth
    raise SSHException("No authentication methods available")
paramiko.ssh_exception.SSHException: No authentication methods available

During handling of the above exception, another exception occurred:

Traceback (most recent call last):
  File "/home/vagrant/nornir/venv/lib/python3.10/site-packages/napalm/base/base.py", line 114, in _netmiko_open
    self._netmiko_device = ConnectHandler(
  File "/home/vagrant/nornir/venv/lib/python3.10/site-packages/netmiko/ssh_dispatcher.py", line 410, in ConnectHandler
    return ConnectionClass(*args, **kwargs)
  File "/home/vagrant/nornir/venv/lib/python3.10/site-packages/netmiko/base_connection.py", line 493, in __init__
    self._open()
  File "/home/vagrant/nornir/venv/lib/python3.10/site-packages/netmiko/base_connection.py", line 498, in _open
    self.establish_connection()
  File "/home/vagrant/nornir/venv/lib/python3.10/site-packages/netmiko/base_connection.py", line 1195, in establish_connection
    raise NetmikoTimeoutException(msg)
netmiko.exceptions.NetmikoTimeoutException: 
A paramiko SSHException occurred during connection creation:

No authentication methods available



During handling of the above exception, another exception occurred:

Traceback (most recent call last):
  File "/home/vagrant/nornir/venv/lib/python3.10/site-packages/nornir/core/task.py", line 98, in start
    r = self.task(self, **self.params)
  File "/home/vagrant/nornir/venv/lib/python3.10/site-packages/nornir_napalm/plugins/tasks/napalm_get.py", line 32, in napalm_get
    device = task.host.get_connection(CONNECTION_NAME, task.nornir.config)
  File "/home/vagrant/nornir/venv/lib/python3.10/site-packages/nornir/core/inventory.py", line 476, in get_connection
    self.open_connection(
  File "/home/vagrant/nornir/venv/lib/python3.10/site-packages/nornir/core/inventory.py", line 528, in open_connection
    conn_obj.open(
  File "/home/vagrant/nornir/venv/lib/python3.10/site-packages/nornir_napalm/plugins/connections/__init__.py", line 57, in open
    connection.open()
  File "/home/vagrant/nornir/venv/lib/python3.10/site-packages/napalm/ios/ios.py", line 173, in open
    self.device = self._netmiko_open(
  File "/home/vagrant/nornir/venv/lib/python3.10/site-packages/napalm/base/base.py", line 123, in _netmiko_open
    raise ConnectionException("Cannot connect to {}".format(self.hostname))
napalm.base.exceptions.ConnectionException: Cannot connect to 192.168.121.101

2025-02-11 11:59:56,266 -  nornir.core -     INFO -        run() - Running task 'napalm_get' with args {'getters': ['interfaces']} on 1 hosts
2025-02-11 11:59:56,267 - nornir.core.task -    ERROR -      start() - Host 'hosts': task 'napalm_get' failed with traceback:
Traceback (most recent call last):
  File "/home/vagrant/nornir/venv/lib/python3.10/site-packages/nornir/core/task.py", line 98, in start
    r = self.task(self, **self.params)
  File "/home/vagrant/nornir/venv/lib/python3.10/site-packages/nornir_napalm/plugins/tasks/napalm_get.py", line 32, in napalm_get
    device = task.host.get_connection(CONNECTION_NAME, task.nornir.config)
  File "/home/vagrant/nornir/venv/lib/python3.10/site-packages/nornir/core/inventory.py", line 476, in get_connection
    self.open_connection(
  File "/home/vagrant/nornir/venv/lib/python3.10/site-packages/nornir/core/inventory.py", line 528, in open_connection
    conn_obj.open(
  File "/home/vagrant/nornir/venv/lib/python3.10/site-packages/nornir_napalm/plugins/connections/__init__.py", line 55, in open
    network_driver = get_network_driver(platform)
  File "/home/vagrant/nornir/venv/lib/python3.10/site-packages/napalm/base/__init__.py", line 70, in get_network_driver
    raise ModuleImportError("Please provide a valid driver name.")
napalm.base.exceptions.ModuleImportError: Please provide a valid driver name.

2025-02-11 12:00:44,991 -  nornir.core -     INFO -        run() - Running task 'napalm_get' with args {'getters': ['interfaces']} on 1 hosts
2025-02-11 12:00:44,991 - nornir.core.task -    ERROR -      start() - Host 'hosts': task 'napalm_get' failed with traceback:
Traceback (most recent call last):
  File "/home/vagrant/nornir/venv/lib/python3.10/site-packages/nornir/core/task.py", line 98, in start
    r = self.task(self, **self.params)
  File "/home/vagrant/nornir/venv/lib/python3.10/site-packages/nornir_napalm/plugins/tasks/napalm_get.py", line 32, in napalm_get
    device = task.host.get_connection(CONNECTION_NAME, task.nornir.config)
  File "/home/vagrant/nornir/venv/lib/python3.10/site-packages/nornir/core/inventory.py", line 476, in get_connection
    self.open_connection(
  File "/home/vagrant/nornir/venv/lib/python3.10/site-packages/nornir/core/inventory.py", line 528, in open_connection
    conn_obj.open(
  File "/home/vagrant/nornir/venv/lib/python3.10/site-packages/nornir_napalm/plugins/connections/__init__.py", line 55, in open
    network_driver = get_network_driver(platform)
  File "/home/vagrant/nornir/venv/lib/python3.10/site-packages/napalm/base/__init__.py", line 70, in get_network_driver
    raise ModuleImportError("Please provide a valid driver name.")
napalm.base.exceptions.ModuleImportError: Please provide a valid driver name.

2025-02-11 12:01:11,799 -  nornir.core -     INFO -        run() - Running task 'napalm_get' with args {'getters': ['interfaces']} on 1 hosts
2025-02-11 12:01:11,800 - nornir.core.task -    ERROR -      start() - Host 'hosts': task 'napalm_get' failed with traceback:
Traceback (most recent call last):
  File "/home/vagrant/nornir/venv/lib/python3.10/site-packages/nornir/core/task.py", line 98, in start
    r = self.task(self, **self.params)
  File "/home/vagrant/nornir/venv/lib/python3.10/site-packages/nornir_napalm/plugins/tasks/napalm_get.py", line 32, in napalm_get
    device = task.host.get_connection(CONNECTION_NAME, task.nornir.config)
  File "/home/vagrant/nornir/venv/lib/python3.10/site-packages/nornir/core/inventory.py", line 476, in get_connection
    self.open_connection(
  File "/home/vagrant/nornir/venv/lib/python3.10/site-packages/nornir/core/inventory.py", line 528, in open_connection
    conn_obj.open(
  File "/home/vagrant/nornir/venv/lib/python3.10/site-packages/nornir_napalm/plugins/connections/__init__.py", line 55, in open
    network_driver = get_network_driver(platform)
  File "/home/vagrant/nornir/venv/lib/python3.10/site-packages/napalm/base/__init__.py", line 70, in get_network_driver
    raise ModuleImportError("Please provide a valid driver name.")
napalm.base.exceptions.ModuleImportError: Please provide a valid driver name.

2025-02-11 12:02:36,553 -  nornir.core -     INFO -        run() - Running task 'napalm_get' with args {'getters': ['interfaces']} on 1 hosts
2025-02-11 12:02:36,553 - nornir.core.task -    ERROR -      start() - Host 'hosts': task 'napalm_get' failed with traceback:
Traceback (most recent call last):
  File "/home/vagrant/nornir/venv/lib/python3.10/site-packages/nornir/core/task.py", line 98, in start
    r = self.task(self, **self.params)
  File "/home/vagrant/nornir/venv/lib/python3.10/site-packages/nornir_napalm/plugins/tasks/napalm_get.py", line 32, in napalm_get
    device = task.host.get_connection(CONNECTION_NAME, task.nornir.config)
  File "/home/vagrant/nornir/venv/lib/python3.10/site-packages/nornir/core/inventory.py", line 476, in get_connection
    self.open_connection(
  File "/home/vagrant/nornir/venv/lib/python3.10/site-packages/nornir/core/inventory.py", line 528, in open_connection
    conn_obj.open(
  File "/home/vagrant/nornir/venv/lib/python3.10/site-packages/nornir_napalm/plugins/connections/__init__.py", line 55, in open
    network_driver = get_network_driver(platform)
  File "/home/vagrant/nornir/venv/lib/python3.10/site-packages/napalm/base/__init__.py", line 70, in get_network_driver
    raise ModuleImportError("Please provide a valid driver name.")
napalm.base.exceptions.ModuleImportError: Please provide a valid driver name.

2025-02-11 12:03:46,522 -  nornir.core -     INFO -        run() - Running task 'napalm_get' with args {'getters': ['interfaces']} on 1 hosts
2025-02-11 12:03:46,523 - nornir.core.task -    ERROR -      start() - Host 'hosts': task 'napalm_get' failed with traceback:
Traceback (most recent call last):
  File "/home/vagrant/nornir/venv/lib/python3.10/site-packages/nornir/core/task.py", line 98, in start
    r = self.task(self, **self.params)
  File "/home/vagrant/nornir/venv/lib/python3.10/site-packages/nornir_napalm/plugins/tasks/napalm_get.py", line 32, in napalm_get
    device = task.host.get_connection(CONNECTION_NAME, task.nornir.config)
  File "/home/vagrant/nornir/venv/lib/python3.10/site-packages/nornir/core/inventory.py", line 476, in get_connection
    self.open_connection(
  File "/home/vagrant/nornir/venv/lib/python3.10/site-packages/nornir/core/inventory.py", line 528, in open_connection
    conn_obj.open(
  File "/home/vagrant/nornir/venv/lib/python3.10/site-packages/nornir_napalm/plugins/connections/__init__.py", line 55, in open
    network_driver = get_network_driver(platform)
  File "/home/vagrant/nornir/venv/lib/python3.10/site-packages/napalm/base/__init__.py", line 70, in get_network_driver
    raise ModuleImportError("Please provide a valid driver name.")
napalm.base.exceptions.ModuleImportError: Please provide a valid driver name.

2025-02-11 12:04:11,104 -  nornir.core -     INFO -        run() - Running task 'napalm_get' with args {'getters': ['interfaces']} on 1 hosts
2025-02-11 12:04:11,105 - nornir.core.task -    ERROR -      start() - Host 'hosts': task 'napalm_get' failed with traceback:
Traceback (most recent call last):
  File "/home/vagrant/nornir/venv/lib/python3.10/site-packages/nornir/core/task.py", line 98, in start
    r = self.task(self, **self.params)
  File "/home/vagrant/nornir/venv/lib/python3.10/site-packages/nornir_napalm/plugins/tasks/napalm_get.py", line 32, in napalm_get
    device = task.host.get_connection(CONNECTION_NAME, task.nornir.config)
  File "/home/vagrant/nornir/venv/lib/python3.10/site-packages/nornir/core/inventory.py", line 476, in get_connection
    self.open_connection(
  File "/home/vagrant/nornir/venv/lib/python3.10/site-packages/nornir/core/inventory.py", line 528, in open_connection
    conn_obj.open(
  File "/home/vagrant/nornir/venv/lib/python3.10/site-packages/nornir_napalm/plugins/connections/__init__.py", line 55, in open
    network_driver = get_network_driver(platform)
  File "/home/vagrant/nornir/venv/lib/python3.10/site-packages/napalm/base/__init__.py", line 70, in get_network_driver
    raise ModuleImportError("Please provide a valid driver name.")
napalm.base.exceptions.ModuleImportError: Please provide a valid driver name.

2025-02-11 12:04:36,916 -  nornir.core -     INFO -        run() - Running task 'napalm_get' with args {'getters': ['interfaces']} on 1 hosts
2025-02-11 12:04:36,917 - nornir.core.task -    ERROR -      start() - Host 'hosts': task 'napalm_get' failed with traceback:
Traceback (most recent call last):
  File "/home/vagrant/nornir/venv/lib/python3.10/site-packages/nornir/core/task.py", line 98, in start
    r = self.task(self, **self.params)
  File "/home/vagrant/nornir/venv/lib/python3.10/site-packages/nornir_napalm/plugins/tasks/napalm_get.py", line 32, in napalm_get
    device = task.host.get_connection(CONNECTION_NAME, task.nornir.config)
  File "/home/vagrant/nornir/venv/lib/python3.10/site-packages/nornir/core/inventory.py", line 476, in get_connection
    self.open_connection(
  File "/home/vagrant/nornir/venv/lib/python3.10/site-packages/nornir/core/inventory.py", line 528, in open_connection
    conn_obj.open(
  File "/home/vagrant/nornir/venv/lib/python3.10/site-packages/nornir_napalm/plugins/connections/__init__.py", line 55, in open
    network_driver = get_network_driver(platform)
  File "/home/vagrant/nornir/venv/lib/python3.10/site-packages/napalm/base/__init__.py", line 70, in get_network_driver
    raise ModuleImportError("Please provide a valid driver name.")
napalm.base.exceptions.ModuleImportError: Please provide a valid driver name.

2025-02-11 12:52:52,997 -  nornir.core -     INFO -        run() - Running task 'napalm_get' with args {'getters': ['interfaces']} on 1 hosts
2025-02-11 12:52:52,998 - nornir.core.task -    ERROR -      start() - Host 'hosts': task 'napalm_get' failed with traceback:
Traceback (most recent call last):
  File "/home/vagrant/nornir/venv/lib/python3.10/site-packages/nornir/core/task.py", line 98, in start
    r = self.task(self, **self.params)
  File "/home/vagrant/nornir/venv/lib/python3.10/site-packages/nornir_napalm/plugins/tasks/napalm_get.py", line 32, in napalm_get
    device = task.host.get_connection(CONNECTION_NAME, task.nornir.config)
  File "/home/vagrant/nornir/venv/lib/python3.10/site-packages/nornir/core/inventory.py", line 476, in get_connection
    self.open_connection(
  File "/home/vagrant/nornir/venv/lib/python3.10/site-packages/nornir/core/inventory.py", line 528, in open_connection
    conn_obj.open(
  File "/home/vagrant/nornir/venv/lib/python3.10/site-packages/nornir_napalm/plugins/connections/__init__.py", line 55, in open
    network_driver = get_network_driver(platform)
  File "/home/vagrant/nornir/venv/lib/python3.10/site-packages/napalm/base/__init__.py", line 70, in get_network_driver
    raise ModuleImportError("Please provide a valid driver name.")
napalm.base.exceptions.ModuleImportError: Please provide a valid driver name.

2025-02-11 13:03:33,991 -  nornir.core -     INFO -        run() - Running task 'get_current_banner' with args {} on 2 hosts
2025-02-11 13:03:34,096 - nornir.core.task -    ERROR -      start() - Host 'r2': task 'netmiko_send_command' failed with traceback:
Traceback (most recent call last):
  File "/home/vagrant/nornir/venv/lib/python3.10/site-packages/netmiko/base_connection.py", line 1142, in establish_connection
    self.remote_conn_pre.connect(**ssh_connect_params)
  File "/home/vagrant/nornir/venv/lib/python3.10/site-packages/paramiko/client.py", line 485, in connect
    self._auth(
  File "/home/vagrant/nornir/venv/lib/python3.10/site-packages/paramiko/client.py", line 819, in _auth
    raise SSHException("No authentication methods available")
paramiko.ssh_exception.SSHException: No authentication methods available

During handling of the above exception, another exception occurred:

Traceback (most recent call last):
  File "/home/vagrant/nornir/venv/lib/python3.10/site-packages/nornir/core/task.py", line 98, in start
    r = self.task(self, **self.params)
  File "/home/vagrant/nornir/venv/lib/python3.10/site-packages/nornir_netmiko/tasks/netmiko_send_command.py", line 26, in netmiko_send_command
    net_connect = task.host.get_connection(CONNECTION_NAME, task.nornir.config)
  File "/home/vagrant/nornir/venv/lib/python3.10/site-packages/nornir/core/inventory.py", line 476, in get_connection
    self.open_connection(
  File "/home/vagrant/nornir/venv/lib/python3.10/site-packages/nornir/core/inventory.py", line 528, in open_connection
    conn_obj.open(
  File "/home/vagrant/nornir/venv/lib/python3.10/site-packages/nornir_netmiko/connections/netmiko.py", line 59, in open
    connection = ConnectHandler(**parameters)
  File "/home/vagrant/nornir/venv/lib/python3.10/site-packages/netmiko/ssh_dispatcher.py", line 410, in ConnectHandler
    return ConnectionClass(*args, **kwargs)
  File "/home/vagrant/nornir/venv/lib/python3.10/site-packages/netmiko/base_connection.py", line 493, in __init__
    self._open()
  File "/home/vagrant/nornir/venv/lib/python3.10/site-packages/netmiko/base_connection.py", line 498, in _open
    self.establish_connection()
  File "/home/vagrant/nornir/venv/lib/python3.10/site-packages/netmiko/base_connection.py", line 1195, in establish_connection
    raise NetmikoTimeoutException(msg)
netmiko.exceptions.NetmikoTimeoutException: 
A paramiko SSHException occurred during connection creation:

No authentication methods available



2025-02-11 13:03:34,096 - nornir.core.task -    ERROR -      start() - Host 'r1': task 'netmiko_send_command' failed with traceback:
Traceback (most recent call last):
  File "/home/vagrant/nornir/venv/lib/python3.10/site-packages/netmiko/base_connection.py", line 1142, in establish_connection
    self.remote_conn_pre.connect(**ssh_connect_params)
  File "/home/vagrant/nornir/venv/lib/python3.10/site-packages/paramiko/client.py", line 485, in connect
    self._auth(
  File "/home/vagrant/nornir/venv/lib/python3.10/site-packages/paramiko/client.py", line 819, in _auth
    raise SSHException("No authentication methods available")
paramiko.ssh_exception.SSHException: No authentication methods available

During handling of the above exception, another exception occurred:

Traceback (most recent call last):
  File "/home/vagrant/nornir/venv/lib/python3.10/site-packages/nornir/core/task.py", line 98, in start
    r = self.task(self, **self.params)
  File "/home/vagrant/nornir/venv/lib/python3.10/site-packages/nornir_netmiko/tasks/netmiko_send_command.py", line 26, in netmiko_send_command
    net_connect = task.host.get_connection(CONNECTION_NAME, task.nornir.config)
  File "/home/vagrant/nornir/venv/lib/python3.10/site-packages/nornir/core/inventory.py", line 476, in get_connection
    self.open_connection(
  File "/home/vagrant/nornir/venv/lib/python3.10/site-packages/nornir/core/inventory.py", line 528, in open_connection
    conn_obj.open(
  File "/home/vagrant/nornir/venv/lib/python3.10/site-packages/nornir_netmiko/connections/netmiko.py", line 59, in open
    connection = ConnectHandler(**parameters)
  File "/home/vagrant/nornir/venv/lib/python3.10/site-packages/netmiko/ssh_dispatcher.py", line 410, in ConnectHandler
    return ConnectionClass(*args, **kwargs)
  File "/home/vagrant/nornir/venv/lib/python3.10/site-packages/netmiko/base_connection.py", line 493, in __init__
    self._open()
  File "/home/vagrant/nornir/venv/lib/python3.10/site-packages/netmiko/base_connection.py", line 498, in _open
    self.establish_connection()
  File "/home/vagrant/nornir/venv/lib/python3.10/site-packages/netmiko/base_connection.py", line 1195, in establish_connection
    raise NetmikoTimeoutException(msg)
netmiko.exceptions.NetmikoTimeoutException: 
A paramiko SSHException occurred during connection creation:

No authentication methods available



2025-02-11 13:03:34,096 - nornir.core.task -    ERROR -      start() - Host 'r2': task 'get_current_banner' failed with traceback:
Traceback (most recent call last):
  File "/home/vagrant/nornir/venv/lib/python3.10/site-packages/nornir/core/task.py", line 98, in start
    r = self.task(self, **self.params)
  File "/home/vagrant/nornir/nornir-project/main.py", line 11, in get_current_banner
    output = task.run(netmiko_send_command, command_string='show running-config | i banner' )
  File "/home/vagrant/nornir/venv/lib/python3.10/site-packages/nornir/core/task.py", line 173, in run
    raise NornirSubTaskError(task=run_task, result=r)
nornir.core.exceptions.NornirSubTaskError: Subtask: netmiko_send_command (failed)


2025-02-11 13:03:34,096 - nornir.core.task -    ERROR -      start() - Host 'r1': task 'get_current_banner' failed with traceback:
Traceback (most recent call last):
  File "/home/vagrant/nornir/venv/lib/python3.10/site-packages/nornir/core/task.py", line 98, in start
    r = self.task(self, **self.params)
  File "/home/vagrant/nornir/nornir-project/main.py", line 11, in get_current_banner
    output = task.run(netmiko_send_command, command_string='show running-config | i banner' )
  File "/home/vagrant/nornir/venv/lib/python3.10/site-packages/nornir/core/task.py", line 173, in run
    raise NornirSubTaskError(task=run_task, result=r)
nornir.core.exceptions.NornirSubTaskError: Subtask: netmiko_send_command (failed)


2025-02-11 13:03:53,778 -  nornir.core -     INFO -        run() - Running task 'get_current_banner' with args {} on 2 hosts
2025-02-11 13:05:33,345 -  nornir.core -     INFO -        run() - Running task 'get_interfaces' with args {} on 2 hosts
2025-02-11 13:06:59,421 -  nornir.core -     INFO -        run() - Running task 'get_interfaces' with args {} on 2 hosts
2025-02-11 13:08:29,144 -  nornir.core -     INFO -        run() - Running task 'napalm_get' with args {'getters': ['interfaces']} on 2 hosts
2025-02-11 13:09:53,449 -  nornir.core -     INFO -        run() - Running task 'napalm_get' with args {'getters': ['bgp_config']} on 2 hosts
2025-02-11 13:11:58,325 -  nornir.core -     INFO -        run() - Running task 'napalm_get' with args {'getters': ['network_instances']} on 2 hosts
2025-02-11 13:16:11,728 -  nornir.core -     INFO -        run() - Running task 'napalm_get' with args {'getters': ['interfaces']} on 2 hosts
2025-02-11 13:24:28,726 -  nornir.core -     INFO -        run() - Running task 'napalm_cli' with args {'commands': ['show interfaces summary']} on 2 hosts
2025-02-11 13:32:02,735 -  nornir.core -     INFO -        run() - Running task 'napalm_cli' with args {'commands': ['show interfaces summary']} on 2 hosts
2025-02-11 13:34:04,779 -  nornir.core -  WARNING -        run() - Task 'napalm_cli' has not been run – 0 hosts selected
2025-02-11 13:34:33,354 -  nornir.core -  WARNING -        run() - Task 'napalm_cli' has not been run – 0 hosts selected
2025-02-11 13:34:41,689 -  nornir.core -     INFO -        run() - Running task 'napalm_cli' with args {'commands': ['show interfaces summary']} on 1 hosts
2025-02-11 13:37:29,218 -  nornir.core -     INFO -        run() - Running task 'napalm_configure' with args {'dry_run': True, 'configuration': 'interface loopback 1000'} on 2 hosts
2025-02-11 13:37:30,959 - nornir.core.task -    ERROR -      start() - Host 'r1': task 'napalm_configure' failed with traceback:
Traceback (most recent call last):
  File "/home/vagrant/nornir/venv/lib/python3.10/site-packages/nornir/core/task.py", line 98, in start
    r = self.task(self, **self.params)
  File "/home/vagrant/nornir/venv/lib/python3.10/site-packages/nornir_napalm/plugins/tasks/napalm_configure.py", line 36, in napalm_configure
    device.load_merge_candidate(filename=filename, config=configuration)
  File "/home/vagrant/nornir/venv/lib/python3.10/site-packages/napalm/ios/ios.py", line 320, in load_merge_candidate
    return_status, msg = self._load_candidate_wrapper(
  File "/home/vagrant/nornir/venv/lib/python3.10/site-packages/napalm/ios/ios.py", line 274, in _load_candidate_wrapper
    (return_status, msg) = self._scp_file(
  File "/home/vagrant/nornir/venv/lib/python3.10/site-packages/napalm/ios/ios.py", line 736, in _scp_file
    return self._xfer_file(
  File "/home/vagrant/nornir/venv/lib/python3.10/site-packages/napalm/ios/ios.py", line 804, in _xfer_file
    raise CommandErrorException(msg)
napalm.base.exceptions.CommandErrorException: SCP file transfers are not enabled. Configure 'ip scp server enable' on the device.

2025-02-11 13:37:30,966 - nornir.core.task -    ERROR -      start() - Host 'r2': task 'napalm_configure' failed with traceback:
Traceback (most recent call last):
  File "/home/vagrant/nornir/venv/lib/python3.10/site-packages/nornir/core/task.py", line 98, in start
    r = self.task(self, **self.params)
  File "/home/vagrant/nornir/venv/lib/python3.10/site-packages/nornir_napalm/plugins/tasks/napalm_configure.py", line 36, in napalm_configure
    device.load_merge_candidate(filename=filename, config=configuration)
  File "/home/vagrant/nornir/venv/lib/python3.10/site-packages/napalm/ios/ios.py", line 320, in load_merge_candidate
    return_status, msg = self._load_candidate_wrapper(
  File "/home/vagrant/nornir/venv/lib/python3.10/site-packages/napalm/ios/ios.py", line 274, in _load_candidate_wrapper
    (return_status, msg) = self._scp_file(
  File "/home/vagrant/nornir/venv/lib/python3.10/site-packages/napalm/ios/ios.py", line 736, in _scp_file
    return self._xfer_file(
  File "/home/vagrant/nornir/venv/lib/python3.10/site-packages/napalm/ios/ios.py", line 804, in _xfer_file
    raise CommandErrorException(msg)
napalm.base.exceptions.CommandErrorException: SCP file transfers are not enabled. Configure 'ip scp server enable' on the device.

2025-02-11 13:38:35,813 -  nornir.core -     INFO -        run() - Running task 'napalm_configure' with args {'dry_run': False, 'configuration': 'interface loopback 1000'} on 2 hosts
2025-02-11 13:38:37,519 - nornir.core.task -    ERROR -      start() - Host 'r1': task 'napalm_configure' failed with traceback:
Traceback (most recent call last):
  File "/home/vagrant/nornir/venv/lib/python3.10/site-packages/nornir/core/task.py", line 98, in start
    r = self.task(self, **self.params)
  File "/home/vagrant/nornir/venv/lib/python3.10/site-packages/nornir_napalm/plugins/tasks/napalm_configure.py", line 36, in napalm_configure
    device.load_merge_candidate(filename=filename, config=configuration)
  File "/home/vagrant/nornir/venv/lib/python3.10/site-packages/napalm/ios/ios.py", line 320, in load_merge_candidate
    return_status, msg = self._load_candidate_wrapper(
  File "/home/vagrant/nornir/venv/lib/python3.10/site-packages/napalm/ios/ios.py", line 274, in _load_candidate_wrapper
    (return_status, msg) = self._scp_file(
  File "/home/vagrant/nornir/venv/lib/python3.10/site-packages/napalm/ios/ios.py", line 736, in _scp_file
    return self._xfer_file(
  File "/home/vagrant/nornir/venv/lib/python3.10/site-packages/napalm/ios/ios.py", line 804, in _xfer_file
    raise CommandErrorException(msg)
napalm.base.exceptions.CommandErrorException: SCP file transfers are not enabled. Configure 'ip scp server enable' on the device.

2025-02-11 13:38:37,538 - nornir.core.task -    ERROR -      start() - Host 'r2': task 'napalm_configure' failed with traceback:
Traceback (most recent call last):
  File "/home/vagrant/nornir/venv/lib/python3.10/site-packages/nornir/core/task.py", line 98, in start
    r = self.task(self, **self.params)
  File "/home/vagrant/nornir/venv/lib/python3.10/site-packages/nornir_napalm/plugins/tasks/napalm_configure.py", line 36, in napalm_configure
    device.load_merge_candidate(filename=filename, config=configuration)
  File "/home/vagrant/nornir/venv/lib/python3.10/site-packages/napalm/ios/ios.py", line 320, in load_merge_candidate
    return_status, msg = self._load_candidate_wrapper(
  File "/home/vagrant/nornir/venv/lib/python3.10/site-packages/napalm/ios/ios.py", line 274, in _load_candidate_wrapper
    (return_status, msg) = self._scp_file(
  File "/home/vagrant/nornir/venv/lib/python3.10/site-packages/napalm/ios/ios.py", line 736, in _scp_file
    return self._xfer_file(
  File "/home/vagrant/nornir/venv/lib/python3.10/site-packages/napalm/ios/ios.py", line 804, in _xfer_file
    raise CommandErrorException(msg)
napalm.base.exceptions.CommandErrorException: SCP file transfers are not enabled. Configure 'ip scp server enable' on the device.

2025-02-11 13:38:43,203 -  nornir.core -     INFO -        run() - Running task 'napalm_configure' with args {'dry_run': False, 'configuration': 'interface loopback 1000'} on 2 hosts
2025-02-11 13:38:44,878 - nornir.core.task -    ERROR -      start() - Host 'r1': task 'napalm_configure' failed with traceback:
Traceback (most recent call last):
  File "/home/vagrant/nornir/venv/lib/python3.10/site-packages/nornir/core/task.py", line 98, in start
    r = self.task(self, **self.params)
  File "/home/vagrant/nornir/venv/lib/python3.10/site-packages/nornir_napalm/plugins/tasks/napalm_configure.py", line 36, in napalm_configure
    device.load_merge_candidate(filename=filename, config=configuration)
  File "/home/vagrant/nornir/venv/lib/python3.10/site-packages/napalm/ios/ios.py", line 320, in load_merge_candidate
    return_status, msg = self._load_candidate_wrapper(
  File "/home/vagrant/nornir/venv/lib/python3.10/site-packages/napalm/ios/ios.py", line 274, in _load_candidate_wrapper
    (return_status, msg) = self._scp_file(
  File "/home/vagrant/nornir/venv/lib/python3.10/site-packages/napalm/ios/ios.py", line 736, in _scp_file
    return self._xfer_file(
  File "/home/vagrant/nornir/venv/lib/python3.10/site-packages/napalm/ios/ios.py", line 804, in _xfer_file
    raise CommandErrorException(msg)
napalm.base.exceptions.CommandErrorException: SCP file transfers are not enabled. Configure 'ip scp server enable' on the device.

2025-02-11 13:38:44,927 - nornir.core.task -    ERROR -      start() - Host 'r2': task 'napalm_configure' failed with traceback:
Traceback (most recent call last):
  File "/home/vagrant/nornir/venv/lib/python3.10/site-packages/nornir/core/task.py", line 98, in start
    r = self.task(self, **self.params)
  File "/home/vagrant/nornir/venv/lib/python3.10/site-packages/nornir_napalm/plugins/tasks/napalm_configure.py", line 36, in napalm_configure
    device.load_merge_candidate(filename=filename, config=configuration)
  File "/home/vagrant/nornir/venv/lib/python3.10/site-packages/napalm/ios/ios.py", line 320, in load_merge_candidate
    return_status, msg = self._load_candidate_wrapper(
  File "/home/vagrant/nornir/venv/lib/python3.10/site-packages/napalm/ios/ios.py", line 274, in _load_candidate_wrapper
    (return_status, msg) = self._scp_file(
  File "/home/vagrant/nornir/venv/lib/python3.10/site-packages/napalm/ios/ios.py", line 736, in _scp_file
    return self._xfer_file(
  File "/home/vagrant/nornir/venv/lib/python3.10/site-packages/napalm/ios/ios.py", line 804, in _xfer_file
    raise CommandErrorException(msg)
napalm.base.exceptions.CommandErrorException: SCP file transfers are not enabled. Configure 'ip scp server enable' on the device.

2025-02-11 13:40:05,977 -  nornir.core -     INFO -        run() - Running task 'napalm_configure' with args {'configuration': 'interface loopback 1000'} on 2 hosts
2025-02-11 13:40:07,663 - nornir.core.task -    ERROR -      start() - Host 'r2': task 'napalm_configure' failed with traceback:
Traceback (most recent call last):
  File "/home/vagrant/nornir/venv/lib/python3.10/site-packages/nornir/core/task.py", line 98, in start
    r = self.task(self, **self.params)
  File "/home/vagrant/nornir/venv/lib/python3.10/site-packages/nornir_napalm/plugins/tasks/napalm_configure.py", line 36, in napalm_configure
    device.load_merge_candidate(filename=filename, config=configuration)
  File "/home/vagrant/nornir/venv/lib/python3.10/site-packages/napalm/ios/ios.py", line 320, in load_merge_candidate
    return_status, msg = self._load_candidate_wrapper(
  File "/home/vagrant/nornir/venv/lib/python3.10/site-packages/napalm/ios/ios.py", line 274, in _load_candidate_wrapper
    (return_status, msg) = self._scp_file(
  File "/home/vagrant/nornir/venv/lib/python3.10/site-packages/napalm/ios/ios.py", line 736, in _scp_file
    return self._xfer_file(
  File "/home/vagrant/nornir/venv/lib/python3.10/site-packages/napalm/ios/ios.py", line 804, in _xfer_file
    raise CommandErrorException(msg)
napalm.base.exceptions.CommandErrorException: SCP file transfers are not enabled. Configure 'ip scp server enable' on the device.

2025-02-11 13:40:07,682 - nornir.core.task -    ERROR -      start() - Host 'r1': task 'napalm_configure' failed with traceback:
Traceback (most recent call last):
  File "/home/vagrant/nornir/venv/lib/python3.10/site-packages/nornir/core/task.py", line 98, in start
    r = self.task(self, **self.params)
  File "/home/vagrant/nornir/venv/lib/python3.10/site-packages/nornir_napalm/plugins/tasks/napalm_configure.py", line 36, in napalm_configure
    device.load_merge_candidate(filename=filename, config=configuration)
  File "/home/vagrant/nornir/venv/lib/python3.10/site-packages/napalm/ios/ios.py", line 320, in load_merge_candidate
    return_status, msg = self._load_candidate_wrapper(
  File "/home/vagrant/nornir/venv/lib/python3.10/site-packages/napalm/ios/ios.py", line 274, in _load_candidate_wrapper
    (return_status, msg) = self._scp_file(
  File "/home/vagrant/nornir/venv/lib/python3.10/site-packages/napalm/ios/ios.py", line 736, in _scp_file
    return self._xfer_file(
  File "/home/vagrant/nornir/venv/lib/python3.10/site-packages/napalm/ios/ios.py", line 804, in _xfer_file
    raise CommandErrorException(msg)
napalm.base.exceptions.CommandErrorException: SCP file transfers are not enabled. Configure 'ip scp server enable' on the device.

2025-02-11 13:42:04,351 -  nornir.core -     INFO -        run() - Running task 'napalm_configure' with args {'dry_run': False, 'configuration': 'interface loopback 1000'} on 2 hosts
2025-02-11 13:42:06,043 - nornir.core.task -    ERROR -      start() - Host 'r1': task 'napalm_configure' failed with traceback:
Traceback (most recent call last):
  File "/home/vagrant/nornir/venv/lib/python3.10/site-packages/nornir/core/task.py", line 98, in start
    r = self.task(self, **self.params)
  File "/home/vagrant/nornir/venv/lib/python3.10/site-packages/nornir_napalm/plugins/tasks/napalm_configure.py", line 36, in napalm_configure
    device.load_merge_candidate(filename=filename, config=configuration)
  File "/home/vagrant/nornir/venv/lib/python3.10/site-packages/napalm/ios/ios.py", line 320, in load_merge_candidate
    return_status, msg = self._load_candidate_wrapper(
  File "/home/vagrant/nornir/venv/lib/python3.10/site-packages/napalm/ios/ios.py", line 274, in _load_candidate_wrapper
    (return_status, msg) = self._scp_file(
  File "/home/vagrant/nornir/venv/lib/python3.10/site-packages/napalm/ios/ios.py", line 736, in _scp_file
    return self._xfer_file(
  File "/home/vagrant/nornir/venv/lib/python3.10/site-packages/napalm/ios/ios.py", line 804, in _xfer_file
    raise CommandErrorException(msg)
napalm.base.exceptions.CommandErrorException: SCP file transfers are not enabled. Configure 'ip scp server enable' on the device.

2025-02-11 13:42:06,091 - nornir.core.task -    ERROR -      start() - Host 'r2': task 'napalm_configure' failed with traceback:
Traceback (most recent call last):
  File "/home/vagrant/nornir/venv/lib/python3.10/site-packages/nornir/core/task.py", line 98, in start
    r = self.task(self, **self.params)
  File "/home/vagrant/nornir/venv/lib/python3.10/site-packages/nornir_napalm/plugins/tasks/napalm_configure.py", line 36, in napalm_configure
    device.load_merge_candidate(filename=filename, config=configuration)
  File "/home/vagrant/nornir/venv/lib/python3.10/site-packages/napalm/ios/ios.py", line 320, in load_merge_candidate
    return_status, msg = self._load_candidate_wrapper(
  File "/home/vagrant/nornir/venv/lib/python3.10/site-packages/napalm/ios/ios.py", line 274, in _load_candidate_wrapper
    (return_status, msg) = self._scp_file(
  File "/home/vagrant/nornir/venv/lib/python3.10/site-packages/napalm/ios/ios.py", line 736, in _scp_file
    return self._xfer_file(
  File "/home/vagrant/nornir/venv/lib/python3.10/site-packages/napalm/ios/ios.py", line 804, in _xfer_file
    raise CommandErrorException(msg)
napalm.base.exceptions.CommandErrorException: SCP file transfers are not enabled. Configure 'ip scp server enable' on the device.

2025-02-11 13:43:22,183 -  nornir.core -     INFO -        run() - Running task 'napalm_cli' with args {'commands': ['ip scp server enable']} on 2 hosts
2025-02-11 13:43:22,775 -  nornir.core -     INFO -        run() - Running task 'napalm_configure' with args {'dry_run': False, 'configuration': 'interface loopback 1000'} on 2 hosts
2025-02-11 13:43:23,964 - nornir.core.task -    ERROR -      start() - Host 'r2': task 'napalm_configure' failed with traceback:
Traceback (most recent call last):
  File "/home/vagrant/nornir/venv/lib/python3.10/site-packages/nornir/core/task.py", line 98, in start
    r = self.task(self, **self.params)
  File "/home/vagrant/nornir/venv/lib/python3.10/site-packages/nornir_napalm/plugins/tasks/napalm_configure.py", line 36, in napalm_configure
    device.load_merge_candidate(filename=filename, config=configuration)
  File "/home/vagrant/nornir/venv/lib/python3.10/site-packages/napalm/ios/ios.py", line 320, in load_merge_candidate
    return_status, msg = self._load_candidate_wrapper(
  File "/home/vagrant/nornir/venv/lib/python3.10/site-packages/napalm/ios/ios.py", line 274, in _load_candidate_wrapper
    (return_status, msg) = self._scp_file(
  File "/home/vagrant/nornir/venv/lib/python3.10/site-packages/napalm/ios/ios.py", line 736, in _scp_file
    return self._xfer_file(
  File "/home/vagrant/nornir/venv/lib/python3.10/site-packages/napalm/ios/ios.py", line 804, in _xfer_file
    raise CommandErrorException(msg)
napalm.base.exceptions.CommandErrorException: SCP file transfers are not enabled. Configure 'ip scp server enable' on the device.

2025-02-11 13:43:24,007 - nornir.core.task -    ERROR -      start() - Host 'r1': task 'napalm_configure' failed with traceback:
Traceback (most recent call last):
  File "/home/vagrant/nornir/venv/lib/python3.10/site-packages/nornir/core/task.py", line 98, in start
    r = self.task(self, **self.params)
  File "/home/vagrant/nornir/venv/lib/python3.10/site-packages/nornir_napalm/plugins/tasks/napalm_configure.py", line 36, in napalm_configure
    device.load_merge_candidate(filename=filename, config=configuration)
  File "/home/vagrant/nornir/venv/lib/python3.10/site-packages/napalm/ios/ios.py", line 320, in load_merge_candidate
    return_status, msg = self._load_candidate_wrapper(
  File "/home/vagrant/nornir/venv/lib/python3.10/site-packages/napalm/ios/ios.py", line 274, in _load_candidate_wrapper
    (return_status, msg) = self._scp_file(
  File "/home/vagrant/nornir/venv/lib/python3.10/site-packages/napalm/ios/ios.py", line 736, in _scp_file
    return self._xfer_file(
  File "/home/vagrant/nornir/venv/lib/python3.10/site-packages/napalm/ios/ios.py", line 804, in _xfer_file
    raise CommandErrorException(msg)
napalm.base.exceptions.CommandErrorException: SCP file transfers are not enabled. Configure 'ip scp server enable' on the device.

2025-02-11 13:47:18,672 -  nornir.core -     INFO -        run() - Running task 'netmiko_send_command' with args {'commands': ['ip scp server enable']} on 2 hosts
2025-02-11 13:47:18,673 - nornir.core.task -    ERROR -      start() - Host 'r1': task 'netmiko_send_command' failed with traceback:
Traceback (most recent call last):
  File "/home/vagrant/nornir/venv/lib/python3.10/site-packages/nornir/core/task.py", line 98, in start
    r = self.task(self, **self.params)
TypeError: netmiko_send_command() missing 1 required positional argument: 'command_string'

2025-02-11 13:47:18,673 - nornir.core.task -    ERROR -      start() - Host 'r2': task 'netmiko_send_command' failed with traceback:
Traceback (most recent call last):
  File "/home/vagrant/nornir/venv/lib/python3.10/site-packages/nornir/core/task.py", line 98, in start
    r = self.task(self, **self.params)
TypeError: netmiko_send_command() missing 1 required positional argument: 'command_string'

2025-02-11 13:48:22,024 -  nornir.core -     INFO -        run() - Running task 'netmiko_send_command' with args {'command_string': 'ip scp server enable'} on 2 hosts
2025-02-11 13:49:19,391 -  nornir.core -     INFO -        run() - Running task 'netmiko_send_config' with args {'command_string': 'ip scp server enable'} on 2 hosts
2025-02-11 13:49:19,875 - nornir.core.task -    ERROR -      start() - Host 'r1': task 'netmiko_send_config' failed with traceback:
Traceback (most recent call last):
  File "/home/vagrant/nornir/venv/lib/python3.10/site-packages/nornir/core/task.py", line 98, in start
    r = self.task(self, **self.params)
  File "/home/vagrant/nornir/venv/lib/python3.10/site-packages/nornir_netmiko/tasks/netmiko_send_config.py", line 42, in netmiko_send_config
    raise ValueError("Must specify either config_commands or config_file")
ValueError: Must specify either config_commands or config_file

2025-02-11 13:49:19,893 - nornir.core.task -    ERROR -      start() - Host 'r2': task 'netmiko_send_config' failed with traceback:
Traceback (most recent call last):
  File "/home/vagrant/nornir/venv/lib/python3.10/site-packages/nornir/core/task.py", line 98, in start
    r = self.task(self, **self.params)
  File "/home/vagrant/nornir/venv/lib/python3.10/site-packages/nornir_netmiko/tasks/netmiko_send_config.py", line 42, in netmiko_send_config
    raise ValueError("Must specify either config_commands or config_file")
ValueError: Must specify either config_commands or config_file

2025-02-11 13:49:53,673 -  nornir.core -     INFO -        run() - Running task 'netmiko_send_config' with args {'config_commands': 'ip scp server enable'} on 2 hosts
2025-02-11 13:50:15,174 -  nornir.core -     INFO -        run() - Running task 'napalm_configure' with args {'dry_run': False, 'configuration': 'interface loopback 1000'} on 2 hosts
